Workbook
Name Slicer_City: #N/A
Name Slicer_City1: #N/A
Name Slicer_City2: #N/A
Name Slicer_District: #N/A
Name Slicer_Property_Type: #N/A
Name Slicer_Status: #N/A

Sheet Property Dataset  
A1: Property_Id | B1: City | C1: District | D1: Property_Type | E1: Built_Up_Area_Sqft | F1: Price_Inr | G1: Price_Per_Sqft_Inr | H1: Bedrooms | I1: Bathrooms | J1: Age_Years | K1: Facing | L1: Amenities | M1: Amenities_Count | N1: Walkability_Score | O1: Monthly_Rental_Estimate_Inr | P1: Annual_Rental_Yield_Pct | Q1: Price_Category | R1: Estimated_Roi_5Yr_Pct | S1: Listing_Date | T1: Days_On_Market | U1: Status | V1: Registration_Days | W1: Is_Gated_Community | X1: Has_Maintenance_Fee | Y1: Monthly_Maintenance_Inr
A2: PROP00001 | B2: Chennai | C2: Anna Nagar | D2: Apartment | E2: 1526 | F2: 10000000 | G2: 6553 | H2: 2 | I2: 1 | J2: 4 | K2: West | L2: Pool; AC; Elevator; Security; Garden; Gym; Library; Playground | M2: 8 | N2: 9 | O2: 35033 | P2: 4.2 | Q2: Premium | R2: 0.4602 | S2: 45582 | T2: 215 | U2: Available | V2: 169 | W2: TRUE | X2: FALSE | Y2: 0 | AA2: Row Labels | AB2: Average of Price_Inr | AD2: Row Labels | AE2: Average of Price_Inr
A3: PROP00002 | B3: Mumbai | C3: Bandra | D3: Studio | E3: 424 | F3: 50000000 | G3: 117924 | H3: 1 | I3: 1 | J3: 6 | K3: South-East | L3: Pool; Elevator; Library; Gym; Parking | M3: 5 | N3: 7 | O3: 192260 | P3: 4.61 | Q3: Luxury | R3: 0.4807 | S3: 45686 | T3: 283 | U3: Available | V3: 50 | W3: FALSE | X3: FALSE | Y3: 100000 | AA3: Chennai | AB3: 10000000 | AD3: FALSE | AE3: 25498766
A4: PROP00003 | B4: Chennai | C4: Anna Nagar | D4: Apartment | E4: 1333 | F4: 10000000 | G4: 7501 | H4: 3 | I4: 1 | J4: 27 | K4: South-East | L4: Pool; Library; Security; Garden | M4: 4 | N4: 9 | O4: 30921 | P4: 3.71 | Q4: Premium | R4: 0.4355 | S4: 45470 | T4: 312 | U4: Available | V4: 48 | W4: TRUE | X4: TRUE | Y4: 20000 | AA4: Hyderabad | AB4: 12000000 | AD4: TRUE | AE4: 26390552
A5: PROP00004 | B5: Pune | C5: Viman Nagar | D5: Independent House | E5: 4121 | F5: 15000000 | G5: 3639 | H5: 3 | I5: 2 | J5: 26 | K5: South-West | L5: Garden; Gym; Playground | M5: 3 | N5: 6 | O5: 42774 | P5: 3.42 | Q5: Premium | R5: 0.4211 | S5: 45576 | T5: 336 | U5: Rented | V5: 84 | W5: FALSE | X5: FALSE | Y5: 0 | AA5: Pune | AB5: 15000000 | AD5: Grand Total | AE5: 25969629
A6: PROP00005 | B6: Bangalore | C6: Indiranagar | D6: Villa | E6: 4020 | F6: 30000000 | G6: 7462 | H6: 5 | I6: 3 | J6: 28 | K6: North | L6: Library; Playground; Garden; Pool; Security; Concierge; Gym | M6: 7 | N6: 7 | O6: 82642 | P6: 3.31 | Q6: Luxury | R6: 0.4153 | S6: 45993 | T6: 198 | U6: Sold | V6: 46 | W6: FALSE | X6: FALSE | Y6: 0 | AA6: Bangalore | AB6: 29798753
A7: PROP00006 | B7: Hyderabad | C7: Jubilee Hills | D7: Apartment | E7: 2599 | F7: 12000000 | G7: 4617 | H7: 3 | I7: 2 | J7: 3 | K7: North-East | L7: Library; Parking; Concierge; Gym; Playground | M7: 5 | N7: 10 | O7: 45239 | P7: 4.52 | Q7: Premium | R7: 0.4762 | S7: 45637 | T7: 328 | U7: Rented | V7: 106 | W7: TRUE | X7: TRUE | Y7: 0 | AA7: Delhi | AB7: 39006069
A8: PROP00007 | B8: Bangalore | C8: Marathahalli | D8: Penthouse | E8: 3004 | F8: 30000000 | G8: 9986 | H8: 6 | I8: 4 | J8: 15 | K8: West | L8: Pool; Playground; Security | M8: 3 | N8: 7 | O8: 118900 | P8: 4.76 | Q8: Luxury | R8: 0.4878 | S8: 46076 | T8: 273 | U8: Available | V8: 47 | W8: TRUE | X8: TRUE | Y8: 0 | AA8: Mumbai | AB8: 49827453
A9: PROP00008 | B9: Hyderabad | C9: Madhapur | D9: Independent House | E9: 3661 | F9: 12000000 | G9: 3277 | H9: 5 | I9: 2 | J9: 29 | K9: North-West | L9: Garden; Security; Library; Playground; Concierge; Parking; Elevator | M9: 7 | N9: 8 | O9: 34493 | P9: 3.45 | Q9: Premium | R9: 0.4225 | S9: 45810 | T9: 302 | U9: Available | V9: 88 | W9: TRUE | X9: TRUE | Y9: 24000 | AA9: Grand Total | AB9: 25969629
A10: PROP00009 | B10: Chennai | C10: T Nagar | D10: Apartment | E10: 1337 | F10: 10000000 | G10: 7479 | H10: 1 | I10: 1 | J10: 27 | K10: North-West | L10: Pool; AC; Garden; Parking; Playground | M10: 5 | N10: 5 | O10: 27205 | P10: 3.26 | Q10: Premium | R10: 0.4132 | S10: 45572 | T10: 209 | U10: Available | V10: 151 | W10: TRUE | X10: TRUE | Y10: 20000
A11: PROP00010 | B11: Chennai | C11: Thiruvanmiyur | D11: Independent House | E11: 3234 | F11: 10000000 | G11: 3092 | H11: 5 | I11: 3 | J11: 27 | K11: West | L11: Gym; Pool; Elevator; Garden; Playground; Parking; Concierge; Library | M11: 8 | N11: 7 | O11: 32476 | P11: 3.9 | Q11: Premium | R11: 0.4449 | S11: 45724 | T11: 39 | U11: Available | V11: 93 | W11: FALSE | X11: TRUE | Y11: 20000 | AA11: Row Labels | AB11: Count of Property_Type
A12: PROP00011 | B12: Chennai | C12: Kilpauk | D12: Apartment | E12: 782 | F12: 10000000 | G12: 12787 | H12: 2 | I12: 1 | J12: 13 | K12: North | L12: Concierge; Garden; Library; Gym; Pool; AC | M12: 6 | N12: 9 | O12: 29420 | P12: 3.53 | Q12: Premium | R12: 0.4265 | S12: 45691 | T12: 339 | U12: Available | V12: 172 | W12: FALSE | X12: TRUE | Y12: 20000 | AA12: Apartment | AB12: 216
A13: PROP00012 | B13: Delhi | C13: Gurgaon | D13: Apartment | E13: 2772 | F13: 40000000 | G13: 14430 | H13: 1 | I13: 2 | J13: 1 | K13: North | L13: Elevator; Concierge; Parking | M13: 3 | N13: 4 | O13: 105340 | P13: 3.16 | Q13: Luxury | R13: 0.408 | S13: 45966 | T13: 207 | U13: Available | V13: 90 | W13: TRUE | X13: TRUE | Y13: 80000 | AA13: Independent House | AB13: 200
A14: PROP00013 | B14: Hyderabad | C14: Jubilee Hills | D14: Studio | E14: 586 | F14: 12000000 | G14: 20477 | H14: 1 | I14: 2 | J14: 6 | K14: South | L14: Playground; Garden; Security; AC; Pool; Parking; Library; Elevator | M14: 8 | N14: 4 | O14: 42423 | P14: 4.24 | Q14: Premium | R14: 0.4621 | S14: 45580 | T14: 110 | U14: Rented | V14: 167 | W14: FALSE | X14: TRUE | Y14: 0 | AA14: Penthouse | AB14: 206
A15: PROP00014 | B15: Mumbai | C15: Bandra | D15: Independent House | E15: 2667 | F15: 50000000 | G15: 18747 | H15: 3 | I15: 2 | J15: 26 | K15: East | L15: Security; AC; Gym; Playground; Elevator; Parking; Concierge | M15: 7 | N15: 6 | O15: 199142 | P15: 4.78 | Q15: Luxury | R15: 0.489 | S15: 45590 | T15: 176 | U15: Available | V15: 83 | W15: TRUE | X15: FALSE | Y15: 0 | AA15: Studio | AB15: 183
A16: PROP00015 | B16: Delhi | C16: South Delhi | D16: Apartment | E16: 2998 | F16: 40000000 | G16: 13342 | H16: 4 | I16: 3 | J16: 1 | K16: East | L16: Playground; Parking; Security | M16: 3 | N16: 4 | O16: 136778 | P16: 4.1 | Q16: Luxury | R16: 0.4552 | S16: 45719 | T16: 354 | U16: Available | V16: 49 | W16: TRUE | X16: TRUE | Y16: 0 | AA16: Villa | AB16: 195
A17: PROP00016 | B17: Hyderabad | C17: Kondapur | D17: Villa | E17: 5520 | F17: 12000000 | G17: 2173 | H17: 4 | I17: 2 | J17: 9 | K17: South | L17: Gym; Playground; Garden; AC; Pool | M17: 5 | N17: 9 | O17: 41197 | P17: 4.12 | Q17: Premium | R17: 0.456 | S17: 45740 | T17: 122 | U17: Rented | V17: 69 | W17: TRUE | X17: TRUE | Y17: 0 | AA17: Grand Total | AB17: 1000
A18: PROP00017 | B18: Mumbai | C18: Bandra | D18: Independent House | E18: 4704 | F18: 50000000 | G18: 10629 | H18: 5 | I18: 2 | J18: 8 | K18: North-West | L18: Pool; Library; Gym; AC | M18: 4 | N18: 10 | O18: 193048 | P18: 4.63 | Q18: Luxury | R18: 0.4817 | S18: 45685 | T18: 115 | U18: Available | V18: 88 | W18: TRUE | X18: TRUE | Y18: 0
A19: PROP00018 | B19: Delhi | C19: Noida | D19: Apartment | E19: 1543 | F19: 40000000 | G19: 25923 | H19: 3 | I19: 2 | J19: 21 | K19: North | L19: Playground; Gym; Pool; Parking; Concierge; Security; Library | M19: 7 | N19: 8 | O19: 128970 | P19: 3.87 | Q19: Luxury | R19: 0.4435 | S19: 45835 | T19: 198 | U19: Available | V19: 59 | W19: TRUE | X19: FALSE | Y19: 80000 | AA19: Row Labels | AB19: Average of Estimated_Roi_5Yr_Pct
A20: PROP00019 | B20: Chennai | C20: Thiruvanmiyur | D20: Apartment | E20: 2529 | F20: 10000000 | G20: 3954 | H20: 2 | I20: 2 | J20: 13 | K20: North-East | L20: Playground; Elevator; Pool | M20: 3 | N20: 6 | O20: 36114 | P20: 4.33 | Q20: Premium | R20: 0.4667 | S20: 45822 | T20: 66 | U20: Available | V20: 171 | W20: TRUE | X20: FALSE | Y20: 0 | AA20: Pune | AB20: 0.44591091
A21: PROP00020 | B21: Chennai | C21: T Nagar | D21: Villa | E21: 7042 | F21: 10000000 | G21: 1420 | H21: 5 | I21: 3 | J21: 17 | K21: South-West | L21: Security; Elevator; Garden | M21: 3 | N21: 7 | O21: 35111 | P21: 4.21 | Q21: Premium | R21: 0.4607 | S21: 45827 | T21: 262 | U21: Available | V21: 84 | W21: FALSE | X21: TRUE | Y21: 20000 | AA21: Bangalore | AB21: 0.44604088
A22: PROP00021 | B22: Delhi | C22: Rohini | D22: Penthouse | E22: 5745 | F22: 40000000 | G22: 6962 | H22: 4 | I22: 2 | J22: 21 | K22: West | L22: Garden; Elevator; Parking; Gym; Library | M22: 5 | N22: 9 | O22: 140751 | P22: 4.22 | Q22: Luxury | R22: 0.4611 | S22: 46082 | T22: 100 | U22: Available | V22: 177 | W22: FALSE | X22: FALSE | Y22: 0 | AA22: Chennai | AB22: 0.44956872
A23: PROP00022 | B23: Bangalore | C23: Koramangala | D23: Apartment | E23: 836 | F23: 30000000 | G23: 35885 | H23: 4 | I23: 2 | J23: 5 | K23: North-West | L23: AC; Concierge; Gym; Security; Pool; Elevator; Garden; Library | M23: 8 | N23: 10 | O23: 124394 | P23: 4.98 | Q23: Luxury | R23: 0.4988 | S23: 45547 | T23: 314 | U23: Available | V23: 143 | W23: FALSE | X23: FALSE | Y23: 60000 | AA23: Delhi | AB23: 0.45061205
A24: PROP00023 | B24: Chennai | C24: Thiruvanmiyur | D24: Studio | E24: 382 | F24: 10000000 | G24: 26178 | H24: 0 | I24: 2 | J24: 24 | K24: North-East | L24: Concierge; Garden; Security; AC; Gym; Parking; Pool | M24: 7 | N24: 5 | O24: 39883 | P24: 4.79 | Q24: Premium | R24: 0.4893 | S24: 46074 | T24: 356 | U24: Available | V24: 128 | W24: TRUE | X24: TRUE | Y24: 20000 | AA24: Hyderabad | AB24: 0.45160544
A25: PROP00024 | B25: Pune | C25: Viman Nagar | D25: Independent House | E25: 3722 | F25: 15000000 | G25: 4030 | H25: 5 | I25: 3 | J25: 1 | K25: South-West | L25: Library; Elevator; Gym; AC | M25: 4 | N25: 10 | O25: 61068 | P25: 4.89 | Q25: Premium | R25: 0.4943 | S25: 45851 | T25: 276 | U25: Sold | V25: 137 | W25: TRUE | X25: FALSE | Y25: 30000 | AA25: Mumbai | AB25: 0.45293333
A26: PROP00025 | B26: Delhi | C26: Dwarka | D26: Studio | E26: 264 | F26: 26959771 | G26: 102120 | H26: 1 | I26: 2 | J26: 21 | K26: North | L26: Library; Parking; Concierge; Pool; Security; Playground; Gym; Elevator | M26: 8 | N26: 6 | O26: 86658 | P26: 3.86 | Q26: Luxury | R26: 0.4429 | S26: 45684 | T26: 168 | U26: Available | V26: 127 | W26: TRUE | X26: FALSE | Y26: 0 | AA26: Grand Total | AB26: 0.4493443
A27: PROP00026 | B27: Delhi | C27: Dwarka | D27: Independent House | E27: 4580 | F27: 40000000 | G27: 8733 | H27: 5 | I27: 3 | J27: 26 | K27: South-East | L27: Concierge; Gym; AC | M27: 3 | N27: 4 | O27: 104574 | P27: 3.14 | Q27: Luxury | R27: 0.4069 | S27: 45489 | T27: 103 | U27: Available | V27: 93 | W27: TRUE | X27: TRUE | Y27: 80000
A28: PROP00027 | B28: Bangalore | C28: Jayanagar | D28: Apartment | E28: 2710 | F28: 30000000 | G28: 11070 | H28: 2 | I28: 2 | J28: 22 | K28: North-East | L28: Playground; Parking; Pool; Library; Concierge | M28: 5 | N28: 7 | O28: 76283 | P28: 3.05 | Q28: Luxury | R28: 0.4026 | S28: 45837 | T28: 102 | U28: Available | V28: 131 | W28: TRUE | X28: TRUE | Y28: 60000 | AA28: Row Labels | AB28: Count of Status
A29: PROP00028 | B29: Chennai | C29: Besant Nagar | D29: Penthouse | E29: 9598 | F29: 10000000 | G29: 1041 | H29: 4 | I29: 2 | J29: 11 | K29: South-West | L29: Library; Playground; Pool; Security; AC; Parking; Gym | M29: 7 | N29: 10 | O29: 26758 | P29: 3.21 | Q29: Premium | R29: 0.4105 | S29: 45786 | T29: 363 | U29: Sold | V29: 147 | W29: TRUE | X29: FALSE | Y29: 20000 | AA29: Available | AB29: 584
A30: PROP00029 | B30: Chennai | C30: Kilpauk | D30: Independent House | E30: 4022 | F30: 10000000 | G30: 2486 | H30: 5 | I30: 3 | J30: 13 | K30: West | L30: Elevator; Security; Playground; Library; Pool; Gym; Parking; Concierge | M30: 8 | N30: 4 | O30: 34497 | P30: 4.14 | Q30: Premium | R30: 0.457 | S30: 45472 | T30: 167 | U30: Available | V30: 156 | W30: TRUE | X30: FALSE | Y30: 20000 | AA30: Rented | AB30: 161
A31: PROP00030 | B31: Delhi | C31: Noida | D31: Independent House | E31: 2645 | F31: 40000000 | G31: 15122 | H31: 4 | I31: 2 | J31: 16 | K31: West | L31: Pool; Garden; Library; AC | M31: 4 | N31: 4 | O31: 143060 | P31: 4.29 | Q31: Luxury | R31: 0.4646 | S31: 45654 | T31: 151 | U31: Available | V31: 53 | W31: TRUE | X31: FALSE | Y31: 80000 | AA31: Sold | AB31: 255
A32: PROP00031 | B32: Delhi | C32: Pitampura | D32: Penthouse | E32: 6023 | F32: 40000000 | G32: 6641 | H32: 5 | I32: 3 | J32: 13 | K32: West | L32: AC; Playground; Elevator; Concierge; Garden; Parking; Security; Pool | M32: 8 | N32: 10 | O32: 112838 | P32: 3.39 | Q32: Luxury | R32: 0.4193 | S32: 46034 | T32: 99 | U32: Sold | V32: 77 | W32: TRUE | X32: FALSE | Y32: 0 | AA32: Grand Total | AB32: 1000
A33: PROP00032 | B33: Chennai | C33: Kilpauk | D33: Penthouse | E33: 7888 | F33: 10000000 | G33: 1267 | H33: 5 | I33: 2 | J33: 26 | K33: North-East | L33: Security; Garden; Playground; Pool | M33: 4 | N33: 4 | O33: 33902 | P33: 4.07 | Q33: Premium | R33: 0.4534 | S33: 45876 | T33: 150 | U33: Available | V33: 171 | W33: TRUE | X33: FALSE | Y33: 20000
A34: PROP00033 | B34: Mumbai | C34: Borivali | D34: Independent House | E34: 3422 | F34: 50000000 | G34: 14611 | H34: 5 | I34: 3 | J34: 10 | K34: South | L34: Gym; Security; Concierge; Elevator | M34: 4 | N34: 5 | O34: 131173 | P34: 3.15 | Q34: Luxury | R34: 0.4074 | S34: 45512 | T34: 289 | U34: Sold | V34: 68 | W34: FALSE | X34: TRUE | Y34: 100000 | AA34: Row Labels | AB34: Average of Days_On_Market
A35: PROP00034 | B35: Mumbai | C35: Borivali | D35: Studio | E35: 560 | F35: 50000000 | G35: 89285 | H35: 0 | I35: 2 | J35: 14 | K35: South | L35: Security; Library; Elevator; Concierge; AC; Gym | M35: 6 | N35: 4 | O35: 142315 | P35: 3.42 | Q35: Luxury | R35: 0.4208 | S35: 45940 | T35: 123 | U35: Available | V35: 70 | W35: TRUE | X35: TRUE | Y35: 100000 | AA35: Bangalore | AB35: 178.87845
A36: PROP00035 | B36: Mumbai | C36: Dadar | D36: Studio | E36: 554 | F36: 50000000 | G36: 90252 | H36: 1 | I36: 2 | J36: 1 | K36: West | L36: Security; Elevator; Concierge; Gym | M36: 4 | N36: 10 | O36: 190652 | P36: 4.58 | Q36: Luxury | R36: 0.4788 | S36: 45516 | T36: 218 | U36: Available | V36: 80 | W36: TRUE | X36: TRUE | Y36: 100000 | AA36: HSR Layout | AB36: 203.10526
A37: PROP00036 | B37: Delhi | C37: Gurgaon | D37: Apartment | E37: 644 | F37: 40000000 | G37: 62111 | H37: 2 | I37: 2 | J37: 19 | K37: North-West | L37: Elevator; Security; Concierge; Gym; Garden; Parking; Playground; Pool | M37: 8 | N37: 8 | O37: 139869 | P37: 4.2 | Q37: Luxury | R37: 0.4598 | S37: 45714 | T37: 14 | U37: Sold | V37: 94 | W37: TRUE | X37: TRUE | Y37: 80000 | AA37: Indiranagar | AB37: 189.54054
A38: PROP00037 | B38: Chennai | C38: Besant Nagar | D38: Penthouse | E38: 3329 | F38: 10000000 | G38: 3003 | H38: 4 | I38: 3 | J38: 16 | K38: South-East | L38: Concierge; Security; Parking; AC; Garden; Playground; Gym; Pool | M38: 8 | N38: 6 | O38: 30350 | P38: 3.64 | Q38: Premium | R38: 0.4321 | S38: 46049 | T38: 356 | U38: Rented | V38: 135 | W38: FALSE | X38: FALSE | Y38: 0 | AA38: Jayanagar | AB38: 166.51613
A39: PROP00038 | B39: Hyderabad | C39: Jubilee Hills | D39: Studio | E39: 295 | F39: 12000000 | G39: 40677 | H39: 1 | I39: 2 | J39: 10 | K39: North-West | L39: Library; AC; Gym | M39: 3 | N39: 7 | O39: 33751 | P39: 3.38 | Q39: Premium | R39: 0.4188 | S39: 45786 | T39: 27 | U39: Sold | V39: 143 | W39: TRUE | X39: FALSE | Y39: 24000 | AA39: Koramangala | AB39: 159.31429
A40: PROP00039 | B40: Delhi | C40: Dwarka | D40: Studio | E40: 312 | F40: 26019572 | G40: 83396 | H40: 0 | I40: 1 | J40: 22 | K40: South-West | L40: Security; AC; Gym; Elevator | M40: 4 | N40: 4 | O40: 108079 | P40: 4.98 | Q40: Luxury | R40: 0.4992 | S40: 46040 | T40: 256 | U40: Available | V40: 69 | W40: FALSE | X40: FALSE | Y40: 0 | AA40: Marathahalli | AB40: 190.90323
...

Sheet Stats 
A19: 1. No Strong outlier visible in property price
A20: 2. Average or Median are mostly Reliable
A21: 3. Data Distribution looks Balanced

Sheet Executive Summary
A1: REAL ESTATE MARKET ANALYSIS - EXECUTIVE SUMMARY
A2: Comprehensive Property Portfolio Performance Report | Data Analysis Project
A3: Report Generated: May 19, 2026 | Dataset: 1,000 Properties | Cities: 6 Major Metro Areas
A5: 1. PORTFOLIO OVERVIEW - KEY PERFORMANCE INDICATORS
A6: Total Properties | B6: Properties Sold | C6: Properties Available | D6: Properties Rented | F6: Median Property Price | G6: Average 5-Year ROI | H6: Median Monthly Rent | I6: Avg Days on Market
A7: ='Dashboard '!A8 -> 1000 | B7: ='Dashboard '!D8 -> 255 | C7: ='Dashboard '!G8 -> 584 | D7: ='Dashboard '!J8 -> 161 | F7: ='Dashboard '!M8 -> 26719298 | G7: ='Dashboard '!P8 -> 0.4493443 | H7: ='Dashboard '!S8 -> 75513 | I7: ='Dashboard '!Y8 -> 180.223
A9: 2. MARKET SEGMENTATION ANALYSIS
A10: 2.1 Price Category Distribution | F10: 2.2 Property Type Performance
A11: Category | B11: Count | C11: Avg Price (₹) | D11: Avg ROI (%) | F11: Property Type | G11: Count | H11: Avg Price (₹) | I11: Avg Rent (₹) | J11: Avg ROI (%)
A12: Premium | B12: ='Additional Analysis'!B5 -> 491 | C12: ='Additional Analysis'!C5 -> 12279022 | D12: ='Additional Analysis'!D5 -> 0.44894929 | F12: Apartment | G12: ='Additional Analysis'!H24 -> 216 | H12: ='Additional Analysis'!I24 -> 26282407 | I12: ='Additional Analysis'!K24 -> 86035.398 | J12: ='Additional Analysis'!L24 -> 0.44588426
A13: Luxury | B13: ='Additional Analysis'!B6 -> 509 | C13: ='Additional Analysis'!C6 -> 39176089 | D13: ='Additional Analysis'!D6 -> 0.44972534 | F13: Independent House | G13: ='Additional Analysis'!H25 -> 200 | H13: ='Additional Analysis'!I25 -> 27670000 | I13: ='Additional Analysis'!K25 -> 91563.46 | J13: ='Additional Analysis'!L25 -> 0.448755
F14: Penthouse | G14: ='Additional Analysis'!H26 -> 206 | H14: ='Additional Analysis'!I26 -> 24300971 | I14: ='Additional Analysis'!K26 -> 82401.379 | J14: ='Additional Analysis'!L26 -> 0.45286359
F15: Studio | G15: ='Additional Analysis'!H27 -> 183 | H15: ='Additional Analysis'!I27 -> 26243875 | I15: ='Additional Analysis'!K27 -> 87835.393 | J15: ='Additional Analysis'!L27 -> 0.4501235
F16: Villa | G16: ='Additional Analysis'!H28 -> 195 | H16: ='Additional Analysis'!I28 -> 25384615 | I16: ='Additional Analysis'!K28 -> 84950.118 | J16: ='Additional Analysis'!L28 -> 0.44933231
A18: 3. GEOGRAPHIC & LOCATION ANALYSIS
A19: 3.1 City-wise Rental Yield | F19: 3.2 Walkability Score Impact
A20: City | B20: Avg Yield (%) | C20: Max Yield (%) | F20: Walkability Score | G20: Count | H20: Avg Price (₹) | I20: Avg ROI (%)
A21: Bangalore | B21: ='Additional Analysis'!H5 -> 3.9205525 | C21: ='Additional Analysis'!I5 -> 4.99 | F21: Low (1-4) | G21: ='Additional Analysis'!B38 -> 146 | H21: ='Additional Analysis'!C38 -> 26916975 | I21: ='Additional Analysis'!E38 -> 0.4470274
A22: Chennai | B22: ='Additional Analysis'!H6 -> 3.9915642 | C22: ='Additional Analysis'!I6 -> 4.99 | F22: Medium (5-6) | G22: ='Additional Analysis'!B39 -> 257 | H22: ='Additional Analysis'!C39 -> 25195794 | I22: ='Additional Analysis'!E39 -> 0.44798366
A23: Delhi | B23: ='Additional Analysis'!H7 -> 4.0123494 | C23: ='Additional Analysis'!I7 -> 5 | F23: High (7-8) | G23: ='Additional Analysis'!B40 -> 289 | H23: ='Additional Analysis'!C40 -> 26372465 | I23: ='Additional Analysis'!E40 -> 0.44879308
A24: Hyderabad | B24: ='Additional Analysis'!H8 -> 4.0319728 | C24: ='Additional Analysis'!I8 -> 4.98 | F24: Very High (9-10) | G24: ='Additional Analysis'!B41 -> 308 | H24: ='Additional Analysis'!C41 -> 25788277 | I24: ='Additional Analysis'!E41 -> 0.45209513
A25: Mumbai | B25: ='Additional Analysis'!H9 -> 4.0589506 | C25: ='Additional Analysis'!I9 -> 4.98
A26: Pune | B26: ='Additional Analysis'!H10 -> 3.9184242 | C26: ='Additional Analysis'!I10 -> 4.96
A28: 4. STATISTICAL SUMMARY & COMMUNITY ANALYSIS
A29: 4.1 Key Metrics Statistical Summary | H29: 4.2 Gated Community Comparison
A30: Metric | B30: Minimum | C30: Maximum | D30: Average | E30: Median | F30: Std Dev | H30: Community Type | I30: Count | J30: Avg Price (₹)
A31: Property Price (₹) | B31: ='Additional Analysis'!B46 -> 10000000 | C31: ='Additional Analysis'!C46 -> 50000000 | D31: ='Additional Analysis'!D46 -> 25969629 | E31: ='Additional Analysis'!E46 -> 26719298 | F31: ='Additional Analysis'!F46 -> 14817491 | H31: Gated Community | I31: ='Additional Analysis'!H14 -> 528 | J31: ='Additional Analysis'!I14 -> 26390552
A32: Built-up Area (sqft) | B32: ='Additional Analysis'!B47 -> 252 | C32: ='Additional Analysis'!C47 -> 9997 | D32: ='Additional Analysis'!D47 -> 3391.764 | E32: ='Additional Analysis'!E47 -> 2898 | F32: ='Additional Analysis'!F47 -> 2523.6851 | H32: Non-Gated | I32: ='Additional Analysis'!H15 -> 472 | J32: ='Additional Analysis'!I15 -> 25498766
A33: Price per SQFT (₹) | B33: ='Additional Analysis'!B48 -> 1001 | C33: ='Additional Analysis'!C48 -> 183885 | D33: ='Additional Analysis'!D48 -> 20668.953 | E33: ='Additional Analysis'!E48 -> 8462 | F33: ='Additional Analysis'!F48 -> 29689.756
A34: Monthly Rent (₹) | B34: ='Additional Analysis'!B49 -> 25201 | C34: ='Additional Analysis'!C49 -> 207519 | D34: ='Additional Analysis'!D49 -> 86510.172 | E34: ='Additional Analysis'!E49 -> 75513 | F34: ='Additional Analysis'!F49 -> 52175.049 | H34: 4.3 Property Status Distribution
A35: ROI 5-Year (%) | B35: ='Additional Analysis'!B50 -> 0.4001 | C35: ='Additional Analysis'!C50 -> 0.4998 | D35: ='Additional Analysis'!D50 -> 0.4493443 | E35: ='Additional Analysis'!E50 -> 0.4489 | F35: ='Additional Analysis'!F50 -> 0.029572427 | H35: Status | I35: Count | J35: Avg Days on Market
A36: Days on Market | B36: ='Additional Analysis'!B51 -> 1 | C36: ='Additional Analysis'!C51 -> 365 | D36: ='Additional Analysis'!D51 -> 180.223 | E36: ='Additional Analysis'!E51 -> 178 | F36: ='Additional Analysis'!F51 -> 104.14143 | H36: Available | I36: ='Additional Analysis'!B55 -> 584 | J36: ='Additional Analysis'!D55 -> 179.10445
H37: Sold | I37: ='Additional Analysis'!B56 -> 255 | J37: ='Additional Analysis'!D56 -> 179.24314
H38: Rented | I38: ='Additional Analysis'!B57 -> 161 | J38: ='Additional Analysis'!D57 -> 185.8323
A40: 5. KEY FINDINGS & STRATEGIC RECOMMENDATIONS
A41: 📊 KEY FINDINGS | F41: 💡 STRATEGIC RECOMMENDATIONS
A42: 1. Portfolio shows balanced distribution: Premium (49.1%) and Luxury (50.9%) properties. | F42: 1. Focus on 3-5 BHK properties in high walkability areas for maximum returns.
A43: 2. Average 5-Year ROI is ~45% with consistent performance across all property types. | F43: 2. Consider Premium category for value-oriented investments with comparable ROI.
A44: 3. Market liquidity is healthy: 58.4% available, 25.5% sold, 16.1% rented. | F44: 3. Prioritize gated communities in tier-1 cities for security-conscious buyers.
A45: 4. High walkability (9-10) areas generate better rental yields (~4.04%). | F45: 4. Target properties with 5+ amenities for higher rental income potential.
...

Sheet Dashboard 
A1: Real Estate Performance Dashboard
A5: 🏠Total Properties | D5: 🏠Sold Properties | G5: 🏠Available Properties | J5: 🏠Rented Properties | M5: 🏠Median Property Price | P5: 💰Average ROI | S5: 💰Median Monthly Rent | V5: Median Price/SQFT | Y5: 🏠Avg. Days On Market
A8: =COUNTA('Property Dataset '!A2:A1001) -> 1000 | D8: =COUNTIF('Property Dataset '!U2:U1001,"SOLD") -> 255 | G8: =COUNTIF('Property Dataset '!U2:U1001,"Available") -> 584 | J8: =COUNTIF('Property Dataset '!U2:U1001,"Rented") -> 161 | M8: 26719298 | P8: 0.4493443 | S8: 75513 | V8: =MEDIAN('Property Dataset '!G2:G1001) -> 8462 | Y8: =AVERAGE('Property Dataset '!T2:T1001) -> 180.223
A77: KEY ADDITIONAL INSIGHTS (Formulas-Based)
A78: 1. Mumbai dominates the premium real estate market and is costiest city in the dataset.
A79: 2. These cities provide comparatively affordable property option.
A80: 3. Apatment-based housing dominates the market inventory.
A81: 4. More than half of the properties are still available.
A82: 5. Mumbai not only has the highest property prices but also strong Investment returns.
A83: 6. ROI differences between cities are small, but Mumbai performs best overall.
A84: 7. Properties typically remain listed for nearly 6 months before sale/rent.
A85: 8. Demand differs significantly by district.
A86: 9. Gated Community properties are priced higher than non-gated properties.
A87: Overall Consulsion The real estate market is dominated by apartment properties and high inventory availability. Mumbai leads in both average property price and ROI, making it the strongest premium investment market. Chennai and Hyderabad provide more affordable alternatives. Gated communities command higher prices due to better amenities and security, while property demand and market activity vary significantly across districts.
A92: CONFIDENTIAL | Real Estate Performance Dashboard | Prepared for Project Review
... A94: © 2026 Real Estate Analytics | Page 1 of 1

Sheet Additional Analysis
A1: Additional Property Analysis - Supplementary Insights
A3: 1. PRICE CATEGORY ANALYSIS | G3: 6. RENTAL YIELD BY CITY
A4: Price Category | B4: Count | C4: Avg Price (₹) | D4: Avg ROI (%) | G4: City | H4: Avg Rental Yield (%) | I4: Max Yield (%)
A5: Premium | B5: =COUNTIF('Property Dataset '!Q:Q,"Premium") -> 491 | C5: =AVERAGEIF('Property Dataset '!Q:Q,"Premium",'Property Dataset '!F:F) -> 12279022 | D5: =AVERAGEIF('Property Dataset '!Q:Q,"Premium",'Property Dataset '!R:R) -> 0.44894929 | G5: Bangalore | H5: =AVERAGEIF('Property Dataset '!B:B,"Bangalore",'Property Dataset '!P:P) -> 3.9205525 | I5: =_xlfn.MAXIFS('Property Dataset '!P:P,'Property Dataset '!B:B,"Bangalore") -> 4.99
A6: Luxury | B6: =COUNTIF('Property Dataset '!Q:Q,"Luxury") -> 509 | C6: =AVERAGEIF('Property Dataset '!Q:Q,"Luxury",'Property Dataset '!F:F) -> 39176089 | D6: =AVERAGEIF('Property Dataset '!Q:Q,"Luxury",'Property Dataset '!R:R) -> 0.44972534 | G6: Chennai | H6: =AVERAGEIF('Property Dataset '!B:B,"Chennai",'Property Dataset '!P:P) -> 3.9915642 | I6: =_xlfn.MAXIFS('Property Dataset '!P:P,'Property Dataset '!B:B,"Chennai") -> 4.99
G7: Delhi | H7: =AVERAGEIF('Property Dataset '!B:B,"Delhi",'Property Dataset '!P:P) -> 4.0123494 | I7: =_xlfn.MAXIFS('Property Dataset '!P:P,'Property Dataset '!B:B,"Delhi") -> 5
A8: 2. BEDROOM DISTRIBUTION ANALYSIS | G8: Hyderabad | H8: =AVERAGEIF('Property Dataset '!B:B,"Hyderabad",'Property Dataset '!P:P) -> 4.0319728 | I8: =_xlfn.MAXIFS('Property Dataset '!P:P,'Property Dataset '!B:B,"Hyderabad") -> 4.98
A9: Bedrooms | B9: Count | C9: % of Total | D9: Avg Price (₹) | E9: Avg Rent (₹) | F9: Avg ROI (%) | G9: Mumbai | H9: =AVERAGEIF('Property Dataset '!B:B,"Mumbai",'Property Dataset '!P:P) -> 4.0589506 | I9: =_xlfn.MAXIFS('Property Dataset '!P:P,'Property Dataset '!B:B,"Mumbai") -> 4.98
A10: 0 BHK | B10: =COUNTIF('Property Dataset '!H:H,0) -> 79 | C10: =B10/1000 -> 0.079 | D10: =AVERAGEIF('Property Dataset '!H:H,0,'Property Dataset '!F:F) -> 24744793 | E10: =AVERAGEIF('Property Dataset '!H:H,0,'Property Dataset '!O:O) -> 84132.848 | F10: =AVERAGEIF('Property Dataset '!H:H,0,'Property Dataset '!R:R) -> 0.45287342 | G10: Pune | H10: =AVERAGEIF('Property Dataset '!B:B,"Pune",'Property Dataset '!P:P) -> 3.9184242 | I10: =_xlfn.MAXIFS('Property Dataset '!P:P,'Property Dataset '!B:B,"Pune") -> 4.96
A11: 1 BHK | B11: =COUNTIF('Property Dataset '!H:H,1) -> 164 | C11: =B11/1000 -> 0.164 | D11: =AVERAGEIF('Property Dataset '!H:H,1,'Property Dataset '!F:F) -> 27486527 | E11: =AVERAGEIF('Property Dataset '!H:H,1,'Property Dataset '!O:O) -> 88738.335 | F11: =AVERAGEIF('Property Dataset '!H:H,1,'Property Dataset '!R:R) -> 0.44392134
A12: 2 BHK | B12: =COUNTIF('Property Dataset '!H:H,2) -> 95 | C12: =B12/1000 -> 0.095 | D12: =AVERAGEIF('Property Dataset '!H:H,2,'Property Dataset '!F:F) -> 27115789 | E12: =AVERAGEIF('Property Dataset '!H:H,2,'Property Dataset '!O:O) -> 93280.653 | F12: =AVERAGEIF('Property Dataset '!H:H,2,'Property Dataset '!R:R) -> 0.45356737 | G12: 7. GATED COMMUNITY COMPARISON
A13: 3 BHK | B13: =COUNTIF('Property Dataset '!H:H,3) -> 156 | C13: =B13/1000 -> 0.156 | D13: =AVERAGEIF('Property Dataset '!H:H,3,'Property Dataset '!F:F) -> 26782051 | E13: =AVERAGEIF('Property Dataset '!H:H,3,'Property Dataset '!O:O) -> 88174.558 | F13: =AVERAGEIF('Property Dataset '!H:H,3,'Property Dataset '!R:R) -> 0.44408397 | G13: Type | H13: Count | I13: Avg Price (₹) | J13: Avg ROI (%) | K13: Avg Days On Market
A14: 4 BHK | B14: =COUNTIF('Property Dataset '!H:H,4) -> 201 | C14: =B14/1000 -> 0.201 | D14: =AVERAGEIF('Property Dataset '!H:H,4,'Property Dataset '!F:F) -> 24601990 | E14: =AVERAGEIF('Property Dataset '!H:H,4,'Property Dataset '!O:O) -> 81897.06 | F14: =AVERAGEIF('Property Dataset '!H:H,4,'Property Dataset '!R:R) -> 0.44975771 | G14: Gated Community | H14: =COUNTIF('Property Dataset '!W:W,TRUE) -> 528 | I14: =AVERAGEIF('Property Dataset '!W:W,TRUE,'Property Dataset '!F:F) -> 26390552 | J14: =AVERAGEIF('Property Dataset '!W:W,TRUE,'Property Dataset '!R:R) -> 0.44871837 | K14: =AVERAGEIF('Property Dataset '!W:W,TRUE,'Property Dataset '!T:T) -> 184.69129
A15: 5 BHK | B15: =COUNTIF('Property Dataset '!H:H,5) -> 184 | C15: =B15/1000 -> 0.184 | D15: =AVERAGEIF('Property Dataset '!H:H,5,'Property Dataset '!F:F) -> 25347826 | E15: =AVERAGEIF('Property Dataset '!H:H,5,'Property Dataset '!O:O) -> 85540.685 | F15: =AVERAGEIF('Property Dataset '!H:H,5,'Property Dataset '!R:R) -> 0.45268804 | G15: Non-Gated | H15: =COUNTIF('Property Dataset '!W:W,FALSE) -> 472 | I15: =AVERAGEIF('Property Dataset '!W:W,FALSE,'Property Dataset '!F:F) -> 25498766 | J15: =AVERAGEIF('Property Dataset '!W:W,FALSE,'Property Dataset '!R:R) -> 0.45004449 | K15: =AVERAGEIF('Property Dataset '!W:W,FALSE,'Property Dataset '!T:T) -> 175.22458
A16: 6 BHK | B16: =COUNTIF('Property Dataset '!H:H,6) -> 121 | C16: =B16/1000 -> 0.121 | D16: =AVERAGEIF('Property Dataset '!H:H,6,'Property Dataset '!F:F) -> 25983471 | E16: =AVERAGEIF('Property Dataset '!H:H,6,'Property Dataset '!O:O) -> 86718.198 | F16: =AVERAGEIF('Property Dataset '!H:H,6,'Property Dataset '!R:R) -> 0.45208512
G17: 8. MAINTENANCE FEE ANALYSIS
A18: 3. PROPERTY AGE ANALYSIS | G18: Has Maintenance | H18: Count | I18: Avg Price (₹) | J18: Avg Monthly Maint. (₹) | K18: Avg ROI (%)
A19: Age Group | B19: Count | C19: Avg Price (₹) | D19: Avg Price/SQFT (₹) | E19: Avg ROI (%) | G19: Yes | H19: =COUNTIF('Property Dataset '!X:X,TRUE) -> 483 | I19: =AVERAGEIF('Property Dataset '!X:X,TRUE,'Property Dataset '!F:F) -> 25816839 | J19: =AVERAGEIF('Property Dataset '!X:X,TRUE,'Property Dataset '!Y:Y) -> 25015.178 | K19: =AVERAGEIF('Property Dataset '!X:X,TRUE,'Property Dataset '!R:R) -> 0.44939876
A20: 0-5 Years (New) | B20: =COUNTIFS('Property Dataset '!J:J,">=0",'Property Dataset '!J:J,"<=5") -> 197 | C20: =AVERAGEIFS('Property Dataset '!F:F,'Property Dataset '!J:J,">=0",'Property Dataset '!J:J,"<=5") -> 25787812 | D20: =AVERAGEIFS('Property Dataset '!G:G,'Property Dataset '!J:J,">=0",'Property Dataset '!J:J,"<=5") -> 23155.98 | E20: =AVERAGEIFS('Property Dataset '!R:R,'Property Dataset '!J:J,">=0",'Property Dataset '!J:J,"<=5") -> 0.44876244 | G20: No | H20: =COUNTIF('Property Dataset '!X:X,FALSE) -> 517 | I20: =AVERAGEIF('Property Dataset '!X:X,FALSE,'Property Dataset '!F:F) -> 26112372 | J20: =AVERAGEIF('Property Dataset '!X:X,FALSE,'Property Dataset '!Y:Y) -> 27185.257 | K20: =AVERAGEIF('Property Dataset '!X:X,FALSE,'Property Dataset '!R:R) -> 0.44929342
A21: 6-10 Years | B21: =COUNTIFS('Property Dataset '!J:J,">=6",'Property Dataset '!J:J,"<=10") -> 170 | C21: =AVERAGEIFS('Property Dataset '!F:F,'Property Dataset '!J:J,">=6",'Property Dataset '!J:J,"<=10") -> 25272759 | D21: =AVERAGEIFS('Property Dataset '!G:G,'Property Dataset '!J:J,">=6",'Property Dataset '!J:J,"<=10") -> 22410.788 | E21: =AVERAGEIFS('Property Dataset '!R:R,'Property Dataset '!J:J,">=6",'Property Dataset '!J:J,"<=10") -> 0.45116235
A22: 11-15 Years | B22: =COUNTIFS('Property Dataset '!J:J,">=11",'Property Dataset '!J:J,"<=15") -> 175 | C22: =AVERAGEIFS('Property Dataset '!F:F,'Property Dataset '!J:J,">=11",'Property Dataset '!J:J,"<=15") -> 26298341 | D22: =AVERAGEIFS('Property Dataset '!G:G,'Property Dataset '!J:J,">=11",'Property Dataset '!J:J,"<=15") -> 21234.154 | E22: =AVERAGEIFS('Property Dataset '!R:R,'Property Dataset '!J:J,">=11",'Property Dataset '!J:J,"<=15") -> 0.44754571 | G22: 9. PROPERTY TYPE PERFORMANCE MATRIX
A23: 16-20 Years | B23: =COUNTIFS('Property Dataset '!J:J,">=16",'Property Dataset '!J:J,"<=20") -> 152 | C23: =AVERAGEIFS('Property Dataset '!F:F,'Property Dataset '!J:J,">=16",'Property Dataset '!J:J,"<=20") -> 26000879 | D23: =AVERAGEIFS('Property Dataset '!G:G,'Property Dataset '!J:J,">=16",'Property Dataset '!J:J,"<=20") -> 21535.507 | E23: =AVERAGEIFS('Property Dataset '!R:R,'Property Dataset '!J:J,">=16",'Property Dataset '!J:J,"<=20") -> 0.45225789 | G23: Property Type | H23: Count | I23: Avg Price (₹) | J23: Avg Area (sqft) | K23: Avg Rent (₹) | L23: Avg ROI (%)
A24: 21-25 Years | B24: =COUNTIFS('Property Dataset '!J:J,">=21",'Property Dataset '!J:J,"<=25") -> 141 | C24: =AVERAGEIFS('Property Dataset '!F:F,'Property Dataset '!J:J,">=21",'Property Dataset '!J:J,"<=25") -> 25679722 | D24: =AVERAGEIFS('Property Dataset '!G:G,'Property Dataset '!J:J,">=21",'Property Dataset '!J:J,"<=25") -> 17126.525 | E24: =AVERAGEIFS('Property Dataset '!R:R,'Property Dataset '!J:J,">=21",'Property Dataset '!J:J,"<=25") -> 0.44570922 | G24: Apartment | H24: =COUNTIF('Property Dataset '!D:D,"Apartment") -> 216 | I24: =AVERAGEIF('Property Dataset '!D:D,"Apartment",'Property Dataset '!F:F) -> 26282407 | J24: =AVERAGEIF('Property Dataset '!D:D,"Apartment",'Property Dataset '!E:E) -> 1711.3426 | K24: =AVERAGEIF('Property Dataset '!D:D,"Apartment",'Property Dataset '!O:O) -> 86035.398 | L24: =AVERAGEIF('Property Dataset '!D:D,"Apartment",'Property Dataset '!R:R) -> 0.44588426
A25: 26-30 Years (Old) | B25: =COUNTIFS('Property Dataset '!J:J,">=26",'Property Dataset '!J:J,"<=30") -> 165 | C25: =AVERAGEIFS('Property Dataset '!F:F,'Property Dataset '!J:J,">=26",'Property Dataset '!J:J,"<=30") -> 26775013 | D25: =AVERAGEIFS('Property Dataset '!G:G,'Property Dataset '!J:J,">=26",'Property Dataset '!J:J,"<=30") -> 17534.406 | E25: =AVERAGEIFS('Property Dataset '!R:R,'Property Dataset '!J:J,">=26",'Property Dataset '!J:J,"<=30") -> 0.45049576 | G25: Independent House | H25: =COUNTIF('Property Dataset '!D:D,"Independent House") -> 200 | I25: =AVERAGEIF('Property Dataset '!D:D,"Independent House",'Property Dataset '!F:F) -> 27670000 | J25: =AVERAGEIF('Property Dataset '!D:D,"Independent House",'Property Dataset '!E:E) -> 3230.105 | K25: =AVERAGEIF('Property Dataset '!D:D,"Independent House",'Property Dataset '!O:O) -> 91563.46 | L25: =AVERAGEIF('Property Dataset '!D:D,"Independent House",'Property Dataset '!R:R) -> 0.448755
G26: Penthouse | H26: =COUNTIF('Property Dataset '!D:D,"Penthouse") -> 206 | I26: =AVERAGEIF('Property Dataset '!D:D,"Penthouse",'Property Dataset '!F:F) -> 24300971 | J26: =AVERAGEIF('Property Dataset '!D:D,"Penthouse",'Property Dataset '!E:E) -> 6515.0194 | K26: =AVERAGEIF('Property Dataset '!D:D,"Penthouse",'Property Dataset '!O:O) -> 82401.379 | L26: =AVERAGEIF('Property Dataset '!D:D,"Penthouse",'Property Dataset '!R:R) -> 0.45286359
A27: 4. AMENITIES IMPACT ANALYSIS | G27: Studio | H27: =COUNTIF('Property Dataset '!D:D,"Studio") -> 183 | I27: =AVERAGEIF('Property Dataset '!D:D,"Studio",'Property Dataset '!F:F) -> 26243875 | J27: =AVERAGEIF('Property Dataset '!D:D,"Studio",'Property Dataset '!E:E) -> 414.24044 | K27: =AVERAGEIF('Property Dataset '!D:D,"Studio",'Property Dataset '!O:O) -> 87835.393 | L27: =AVERAGEIF('Property Dataset '!D:D,"Studio",'Property Dataset '!R:R) -> 0.4501235
A28: Amenities Count | B28: Properties | C28: Avg Price (₹) | D28: Avg Rent (₹) | E28: Avg ROI (%) | G28: Villa | H28: =COUNTIF('Property Dataset '!D:D,"Villa") -> 195 | I28: =AVERAGEIF('Property Dataset '!D:D,"Villa",'Property Dataset '!F:F) -> 25384615 | J28: =AVERAGEIF('Property Dataset '!D:D,"Villa",'Property Dataset '!E:E) -> 4913.8103 | K28: =AVERAGEIF('Property Dataset '!D:D,"Villa",'Property Dataset '!O:O) -> 84950.118 | L28: =AVERAGEIF('Property Dataset '!D:D,"Villa",'Property Dataset '!R:R) -> 0.44933231
A29: 3 Amenities | B29: =COUNTIF('Property Dataset '!M:M,3) -> 170 | C29: =AVERAGEIF('Property Dataset '!M:M,3,'Property Dataset '!F:F) -> 26401036 | D29: =AVERAGEIF('Property Dataset '!M:M,3,'Property Dataset '!O:O) -> 87436.147 | E29: =AVERAGEIF('Property Dataset '!M:M,3,'Property Dataset '!R:R) -> 0.44830706
A30: 4 Amenities | B30: =COUNTIF('Property Dataset '!M:M,4) -> 174 | C30: =AVERAGEIF('Property Dataset '!M:M,4,'Property Dataset '!F:F) -> 25835885 | D30: =AVERAGEIF('Property Dataset '!M:M,4,'Property Dataset '!O:O) -> 86039.362 | E30: =AVERAGEIF('Property Dataset '!M:M,4,'Property Dataset '!R:R) -> 0.44950632 | G30: 10. FACING DIRECTION ANALYSIS
A31: 5 Amenities | B31: =COUNTIF('Property Dataset '!M:M,5) -> 149 | C31: =AVERAGEIF('Property Dataset '!M:M,5,'Property Dataset '!F:F) -> 25738835 | D31: =AVERAGEIF('Property Dataset '!M:M,5,'Property Dataset '!O:O) -> 86833.966 | E31: =AVERAGEIF('Property Dataset '!M:M,5,'Property Dataset '!R:R) -> 0.4502745 | G31: Facing | H31: Count | I31: Avg Price (₹) | J31: Avg ROI (%)
A32: 6 Amenities | B32: =COUNTIF('Property Dataset '!M:M,6) -> 153 | C32: =AVERAGEIF('Property Dataset '!M:M,6,'Property Dataset '!F:F) -> 27065259 | D32: =AVERAGEIF('Property Dataset '!M:M,6,'Property Dataset '!O:O) -> 90466.085 | E32: =AVERAGEIF('Property Dataset '!M:M,6,'Property Dataset '!R:R) -> 0.44889085 | G32: North | H32: =COUNTIF('Property Dataset '!K:K,"North") -> 139 | I32: =AVERAGEIF('Property Dataset '!K:K,"North",'Property Dataset '!F:F) -> 26340684 | J32: =AVERAGEIF('Property Dataset '!K:K,"North",'Property Dataset '!R:R) -> 0.45159281
A33: 7 Amenities | B33: =COUNTIF('Property Dataset '!M:M,7) -> 173 | C33: =AVERAGEIF('Property Dataset '!M:M,7,'Property Dataset '!F:F) -> 25495290 | D33: =AVERAGEIF('Property Dataset '!M:M,7,'Property Dataset '!O:O) -> 84693.029 | E33: =AVERAGEIF('Property Dataset '!M:M,7,'Property Dataset '!R:R) -> 0.44955607 | G33: South | H33: =COUNTIF('Property Dataset '!K:K,"South") -> 125 | I33: =AVERAGEIF('Property Dataset '!K:K,"South",'Property Dataset '!F:F) -> 26962362 | J33: =AVERAGEIF('Property Dataset '!K:K,"South",'Property Dataset '!R:R) -> 0.4471872
A34: 8 Amenities | B34: =COUNTIF('Property Dataset '!M:M,8) -> 181 | C34: =AVERAGEIF('Property Dataset '!M:M,8,'Property Dataset '!F:F) -> 25410236 | D34: =AVERAGEIF('Property Dataset '!M:M,8,'Property Dataset '!O:O) -> 84219.403 | E34: =AVERAGEIF('Property Dataset '!M:M,8,'Property Dataset '!R:R) -> 0.4495779 | G34: East | H34: =COUNTIF('Property Dataset '!K:K,"East") -> 125 | I34: =AVERAGEIF('Property Dataset '!K:K,"East",'Property Dataset '!F:F) -> 27806189 | J34: =AVERAGEIF('Property Dataset '!K:K,"East",'Property Dataset '!R:R) -> 0.4499392
G35: West | H35: =COUNTIF('Property Dataset '!K:K,"West") -> 126 | I35: =AVERAGEIF('Property Dataset '!K:K,"West",'Property Dataset '!F:F) -> 23756501 | J35: =AVERAGEIF('Property Dataset '!K:K,"West",'Property Dataset '!R:R) -> 0.44841905
A36: 5. WALKABILITY SCORE ANALYSIS | G36: North-East | H36: =COUNTIF('Property Dataset '!K:K,"North-East") -> 120 | I36: =AVERAGEIF('Property Dataset '!K:K,"North-East",'Property Dataset '!F:F) -> 25892336 | J36: =AVERAGEIF('Property Dataset '!K:K,"North-East",'Property Dataset '!R:R) -> 0.44962417
A37: Walkability Score | B37: Count | C37: Avg Price (₹) | D37: Avg Rental Yield (%) | E37: Avg ROI (%) | G37: North-West | H37: =COUNTIF('Property Dataset '!K:K,"North-West") -> 125 | I37: =AVERAGEIF('Property Dataset '!K:K,"North-West",'Property Dataset '!F:F) -> 26237171 | J37: =AVERAGEIF('Property Dataset '!K:K,"North-West",'Property Dataset '!R:R) -> 0.45058
A38: Low (1-4) | B38: =COUNTIFS('Property Dataset '!N:N,">=1",'Property Dataset '!N:N,"<=4") -> 146 | C38: =AVERAGEIFS('Property Dataset '!F:F,'Property Dataset '!N:N,">=1",'Property Dataset '!N:N,"<=4") -> 26916975 | D38: =AVERAGEIFS('Property Dataset '!P:P,'Property Dataset '!N:N,">=1",'Property Dataset '!N:N,"<=4") -> 3.940274 | E38: =AVERAGEIFS('Property Dataset '!R:R,'Property Dataset '!N:N,">=1",'Property Dataset '!N:N,"<=4") -> 0.4470274 | G38: South-East | H38: =COUNTIF('Property Dataset '!K:K,"South-East") -> 116 | I38: =AVERAGEIF('Property Dataset '!K:K,"South-East",'Property Dataset '!F:F) -> 25719594 | J38: =AVERAGEIF('Property Dataset '!K:K,"South-East",'Property Dataset '!R:R) -> 0.44983793
A39: Medium (5-6) | B39: =COUNTIFS('Property Dataset '!N:N,">=5",'Property Dataset '!N:N,"<=6") -> 257 | C39: =AVERAGEIFS('Property Dataset '!F:F,'Property Dataset '!N:N,">=5",'Property Dataset '!N:N,"<=6") -> 25195794 | D39: =AVERAGEIFS('Property Dataset '!P:P,'Property Dataset '!N:N,">=5",'Property Dataset '!N:N,"<=6") -> 3.9598833 | E39: =AVERAGEIFS('Property Dataset '!R:R,'Property Dataset '!N:N,">=5",'Property Dataset '!N:N,"<=6") -> 0.44798366 | G39: South-West | H39: =COUNTIF('Property Dataset '!K:K,"South-West") -> 124 | I39: =AVERAGEIF('Property Dataset '!K:K,"South-West",'Property Dataset '!F:F) -> 24989406 | J39: =AVERAGEIF('Property Dataset '!K:K,"South-West",'Property Dataset '!R:R) -> 0.44736048
A40: High (7-8) | B40: =COUNTIFS('Property Dataset '!N:N,">=7",'Property Dataset '!N:N,"<=8") -> 289 | C40: =AVERAGEIFS('Property Dataset '!F:F,'Property Dataset '!N:N,">=7",'Property Dataset '!N:N,"<=8") -> 26372465 | D40: =AVERAGEIFS('Property Dataset '!P:P,'Property Dataset '!N:N,">=7",'Property Dataset '!N:N,"<=8") -> 3.9761246 | E40: =AVERAGEIFS('Property Dataset '!R:R,'Property Dataset '!N:N,">=7",'Property Dataset '!N:N,"<=8") -> 0.44879308
A41: Very High (9-10) | B41: =COUNTIFS('Property Dataset '!N:N,">=9",'Property Dataset '!N:N,"<=10") -> 308 | C41: =AVERAGEIFS('Property Dataset '!F:F,'Property Dataset '!N:N,">=9",'Property Dataset '!N:N,"<=10") -> 25788277 | D41: =AVERAGEIFS('Property Dataset '!P:P,'Property Dataset '!N:N,">=9",'Property Dataset '!N:N,"<=10") -> 4.0418182 | E41: =AVERAGEIFS('Property Dataset '!R:R,'Property Dataset '!N:N,">=9",'Property Dataset '!N:N,"<=10") -> 0.45209513
...
